Workbook
Name Slicer_Account: #N/A
Name Slicer_Agent: #N/A
Name Slicer_Category: #N/A
Name Slicer_Department: #N/A
Name Slicer_Region: #N/A

Sheet SQL_Import
A1: Ticket_ID | B1: Account | C1: Created_Date | D1: Closed_Date | E1: Category | F1: Subcategory | G1: Priority | H1: Agent | I1: Department | J1: Resolution_Time | K1: SLA_Target | L1: SLA_Met | M1: Customer_rating | N1: Reopened | O1: Ticket_Status | P1: Resolution_type | Q1: Region | R1: Calculated_SLA | S1: SLA_Mismatch | T1: SLA_score | U1: Subcategory_Validation
A2: TKT000001 | B2: United Overseas Bank | C2: 2026-03-17 16:17:00 | D2: 2026-03-18 07:18:00 | E2: Connectivity & Software | F2: Network Dropouts | G2: Low | H2: Michael | I2: Network Team | J2: 15.2 | K2: 24 | L2: Yes | M2: 4 | N2: No | O2: Closed | P2: Fixed | Q2: South | R2: =IF(Table14[[#This Row],[Resolution_Time]]>Table14[[#This Row],[SLA_Target]],"No", "Yes") -> Yes | S2: =IF(Table14[[#This Row],[Calculated_SLA]]=Table14[[#This Row],[SLA_Met]],"Match","Mismatch") -> Match | T2: =IF(Table14[[#This Row],[Calculated_SLA]]="Yes",1,0) -> 1 | U2: =IF(COUNTIFS(Reference_data!A:A,Table14[[#This Row],[Category]],Reference_data!B:B,Table14[[#This Row],[Subcategory]])>0,"Valid","Invalid") -> Valid
A3: TKT000002 | B3: Amazon Ltd | C3: 2026-03-21 13:21:00 | D3: 2026-03-21 18:21:00 | E3: Print Quality | F3: Finishing Errors | G3: Low | H3: Tina | I3: Field Support | J3: 5 | K3: 24 | L3: No | M3: 3 | N3: Yes | O3: Closed | P3: Temporary Workaround | Q3: West | R3: =IF(Table14[[#This Row],[Resolution_Time]]>Table14[[#This Row],[SLA_Target]],"No", "Yes") -> Yes | S3: =IF(Table14[[#This Row],[Calculated_SLA]]=Table14[[#This Row],[SLA_Met]],"Match","Mismatch") -> Mismatch | T3: =IF(Table14[[#This Row],[Calculated_SLA]]="Yes",1,0) -> 1 | U3: =IF(COUNTIFS(Reference_data!A:A,Table14[[#This Row],[Category]],Reference_data!B:B,Table14[[#This Row],[Subcategory]])>0,"Valid","Invalid") -> Valid
A4: TKT000003 | B4: Tata Consultancy Services Ltd | C4: 2026-03-25 14:25:00 | D4: 2026-03-25 18:25:00 | E4: Contract & Billing | F4: Relocation Requests | G4: Medium | H4: Emma | I4: Billing Team | J4: 3.3 | K4: 8 | L4: Yes | M4: 4 | N4: No | O4: Closed | P4: Fixed | Q4: South | R4: =IF(Table14[[#This Row],[Resolution_Time]]>Table14[[#This Row],[SLA_Target]],"No", "Yes") -> Yes | S4: =IF(Table14[[#This Row],[Calculated_SLA]]=Table14[[#This Row],[SLA_Met]],"Match","Mismatch") -> Match | T4: =IF(Table14[[#This Row],[Calculated_SLA]]="Yes",1,0) -> 1 | U4: =IF(COUNTIFS(Reference_data!A:A,Table14[[#This Row],[Category]],Reference_data!B:B,Table14[[#This Row],[Subcategory]])>0,"Valid","Invalid") -> Valid
A5: TKT000004 | B5: HDFC Bank Ltd | C5: 2026-03-22 08:22:00 | D5: 2026-03-22 15:22:00 | E5: Print Quality | F5: Color Calibration | G5: High | H5: James | I5: Remote Support | J5: 6.9 | K5: 4 | L5: No | M5: 1 | N5: No | O5: Closed | P5: Escalated | Q5: North | R5: =IF(Table14[[#This Row],[Resolution_Time]]>Table14[[#This Row],[SLA_Target]],"No", "Yes") -> No | S5: =IF(Table14[[#This Row],[Calculated_SLA]]=Table14[[#This Row],[SLA_Met]],"Match","Mismatch") -> Match | T5: =IF(Table14[[#This Row],[Calculated_SLA]]="Yes",1,0) -> 0 | U5: =IF(COUNTIFS(Reference_data!A:A,Table14[[#This Row],[Category]],Reference_data!B:B,Table14[[#This Row],[Subcategory]])>0,"Valid","Invalid") -> Valid
A6: TKT000005 | B6: ICICI Bank Ltd | C6: 2026-01-27 12:27:00 | D6: 2026-01-27 22:27:00 | E6: Connectivity & Software | F6: Driver & Setup | G6: Medium | H6: Sarah | I6: Network Team | J6: 10.1 | K6: 8 | L6: No | M6: 1 | N6: No | O6: Closed | P6: Temporary Workaround | Q6: North | R6: =IF(Table14[[#This Row],[Resolution_Time]]>Table14[[#This Row],[SLA_Target]],"No", "Yes") -> No | S6: =IF(Table14[[#This Row],[Calculated_SLA]]=Table14[[#This Row],[SLA_Met]],"Match","Mismatch") -> Match | T6: =IF(Table14[[#This Row],[Calculated_SLA]]="Yes",1,0) -> 0 | U6: =IF(COUNTIFS(Reference_data!A:A,Table14[[#This Row],[Category]],Reference_data!B:B,Table14[[#This Row],[Subcategory]])>0,"Valid","Invalid") -> Valid
A7: TKT000006 | B7: LIC Corp Ltd | C7: 2026-01-17 11:17:00 | D7: 2026-01-17 23:17:00 | E7: Connectivity & Software | F7: Scan-to-Email | G7: Medium | H7: Judy | I7: Network Team | J7: 12 | K7: 8 | L7: No | M7: 3 | N7: No | O7: Closed | P7: Escalated | Q7: West | R7: =IF(Table14[[#This Row],[Resolution_Time]]>Table14[[#This Row],[SLA_Target]],"No", "Yes") -> No | S7: =IF(Table14[[#This Row],[Calculated_SLA]]=Table14[[#This Row],[SLA_Met]],"Match","Mismatch") -> Match | T7: =IF(Table14[[#This Row],[Calculated_SLA]]="Yes",1,0) -> 0 | U7: =IF(COUNTIFS(Reference_data!A:A,Table14[[#This Row],[Category]],Reference_data!B:B,Table14[[#This Row],[Subcategory]])>0,"Valid","Invalid") -> Valid
A8: TKT000007 | B8: Amazon Ltd | C8: 2026-03-17 13:17:00 | D8: 2026-03-17 17:17:00 | E8: Connectivity & Software | F8: Scan-to-Email | G8: Medium | H8: Emma | I8: Network Team | J8: 4.9 | K8: 8 | L8: Yes | M8: 4 | N8: No | O8: Closed | P8: Fixed | Q8: West | R8: =IF(Table14[[#This Row],[Resolution_Time]]>Table14[[#This Row],[SLA_Target]],"No", "Yes") -> Yes | S8: =IF(Table14[[#This Row],[Calculated_SLA]]=Table14[[#This Row],[SLA_Met]],"Match","Mismatch") -> Match | T8: =IF(Table14[[#This Row],[Calculated_SLA]]="Yes",1,0) -> 1 | U8: =IF(COUNTIFS(Reference_data!A:A,Table14[[#This Row],[Category]],Reference_data!B:B,Table14[[#This Row],[Subcategory]])>0,"Valid","Invalid") -> Valid
A9: TKT000008 | B9: Reliance Ltd | C9: 2026-03-20 14:20:00 | D9: 2026-03-21 03:21:00 | E9: Hardware & Mechanical | F9: Device Errors | G9: Medium | H9: Judy | I9: Hardware Team | J9: 13.5 | K9: 8 | L9: No | M9: 1 | N9: No | O9: Closed | P9: Temporary Workaround | Q9: West | R9: =IF(Table14[[#This Row],[Resolution_Time]]>Table14[[#This Row],[SLA_Target]],"No", "Yes") -> No | S9: =IF(Table14[[#This Row],[Calculated_SLA]]=Table14[[#This Row],[SLA_Met]],"Match","Mismatch") -> Match | T9: =IF(Table14[[#This Row],[Calculated_SLA]]="Yes",1,0) -> 0 | U9: =IF(COUNTIFS(Reference_data!A:A,Table14[[#This Row],[Category]],Reference_data!B:B,Table14[[#This Row],[Subcategory]])>0,"Valid","Invalid") -> Valid
A10: TKT000009 | B10: Amazon Ltd | C10: 2026-03-17 13:17:00 | D10: 2026-03-17 23:17:00 | E10: Supplies & Logistics | F10: Paper Supply | G10: Medium | H10: Mary | I10: Logistics Team | J10: 9.5 | K10: 8 | L10: No | M10: 3 | N10: No | O10: Closed | P10: Temporary Workaround | Q10: West | R10: =IF(Table14[[#This Row],[Resolution_Time]]>Table14[[#This Row],[SLA_Target]],"No", "Yes") -> No | S10: =IF(Table14[[#This Row],[Calculated_SLA]]=Table14[[#This Row],[SLA_Met]],"Match","Mismatch") -> Match | T10: =IF(Table14[[#This Row],[Calculated_SLA]]="Yes",1,0) -> 0 | U10: =IF(COUNTIFS(Reference_data!A:A,Table14[[#This Row],[Category]],Reference_data!B:B,Table14[[#This Row],[Subcategory]])>0,"Valid","Invalid") -> Valid
A11: TKT000010 | B11: Amazon Ltd | C11: 2026-02-09 13:09:00 | D11: 2026-02-10 04:10:00 | E11: Connectivity & Software | F11: Network Dropouts | G11: High | H11: Tony | I11: Network Team | J11: 14.8 | K11: 4 | L11: No | M11: 2 | N11: No | O11: Closed | P11: Escalated | Q11: North | R11: =IF(Table14[[#This Row],[Resolution_Time]]>Table14[[#This Row],[SLA_Target]],"No", "Yes") -> No | S11: =IF(Table14[[#This Row],[Calculated_SLA]]=Table14[[#This Row],[SLA_Met]],"Match","Mismatch") -> Match | T11: =IF(Table14[[#This Row],[Calculated_SLA]]="Yes",1,0) -> 0 | U11: =IF(COUNTIFS(Reference_data!A:A,Table14[[#This Row],[Category]],Reference_data!B:B,Table14[[#This Row],[Subcategory]])>0,"Valid","Invalid") -> Valid
A12: TKT000011 | B12: HDFC Bank Ltd | C12: 2026-03-09 13:09:00 | D12: 2026-03-10 03:10:00 | E12: Hardware & Mechanical | F12: Device Errors | G12: Low | H12: Mary | I12: Hardware Team | J12: 14.5 | K12: 24 | L12: Yes | M12: 4 | N12: No | O12: Closed | P12: Fixed | Q12: West | R12: =IF(Table14[[#This Row],[Resolution_Time]]>Table14[[#This Row],[SLA_Target]],"No", "Yes") -> Yes | S12: =IF(Table14[[#This Row],[Calculated_SLA]]=Table14[[#This Row],[SLA_Met]],"Match","Mismatch") -> Match | T12: =IF(Table14[[#This Row],[Calculated_SLA]]="Yes",1,0) -> 1 | U12: =IF(COUNTIFS(Reference_data!A:A,Table14[[#This Row],[Category]],Reference_data!B:B,Table14[[#This Row],[Subcategory]])>0,"Valid","Invalid") -> Valid
A13: TKT000012 | B13: Amazon Ltd | C13: 2026-03-05 16:05:00 | D13: 2026-03-06 05:06:00 | E13: Connectivity & Software | F13: Network Dropouts | G13: Medium | H13: James | I13: Network Team | J13: 12.8 | K13: 8 | L13: No | M13: 2 | N13: No | O13: Closed | P13: Escalated | Q13: West | R13: =IF(Table14[[#This Row],[Resolution_Time]]>Table14[[#This Row],[SLA_Target]],"No", "Yes") -> No | S13: =IF(Table14[[#This Row],[Calculated_SLA]]=Table14[[#This Row],[SLA_Met]],"Match","Mismatch") -> Match | T13: =IF(Table14[[#This Row],[Calculated_SLA]]="Yes",1,0) -> 0 | U13: =IF(COUNTIFS(Reference_data!A:A,Table14[[#This Row],[Category]],Reference_data!B:B,Table14[[#This Row],[Subcategory]])>0,"Valid","Invalid") -> Valid
... A18: TKT000017 | B18: HDFC Bank Ltd | C18: 2026-02-15 15:15:00 | D18: 2026-02-15 20:15:00 | E18: Supplies & Logistics | F18: Toner Replenishment | G18: Medium | H18: Judy | I18: Logistics Team | J18: 5.2 | K18: 8 | L18: Yes | M18: 4 | N18: No | O18: Closed | P18: Fixed | Q18: North | R18: =IF(Table14[[#This Row],[Resolution_Time]]>Table14[[#This Row],[SLA_Target]],"No", "Yes") -> Yes | S18: =IF(Table14[[#This Row],[Calculated_SLA]]=Table14[[#This Row],[SLA_Met]],"Match","Mismatch") -> Match | T18: =IF(Table14[[#This Row],[Calculated_SLA]]="Yes",1,0) -> 1 | U18: =IF(COUNTIFS(Reference_data!A:A,Table14[[#This Row],[Category]],Reference_data!B:B,Table14[[#This Row],[Subcategory]])>0,"Valid","Invalid") -> Valid
A19: TKT000018 | B19: HDFC Bank Ltd | C19: 2026-01-06 12:06:00 | D19: 2026-01-06 21:06:00 | E19: Hardware & Mechanical | F19: Device Errors | G19: Medium | H19: Sarah | I19: Hardware Team | J19: 9.2 | K19: 8 | L19: No | M19: \N | N19: Yes | O19: Closed | P19: Escalated | Q19: West | R19: =IF(Table14[[#This Row],[Resolution_Time]]>Table14[[#This Row],[SLA_Target]],"No", "Yes") -> No | S19: =IF(Table14[[#This Row],[Calculated_SLA]]=Table14[[#This Row],[SLA_Met]],"Match","Mismatch") -> Match | T19: =IF(Table14[[#This Row],[Calculated_SLA]]="Yes",1,0) -> 0 | U19: =IF(COUNTIFS(Reference_data!A:A,Table14[[#This Row],[Category]],Reference_data!B:B,Table14[[#This Row],[Subcategory]])>0,"Valid","Invalid") -> Valid
A20: TKT000019 | B20: Bajaj Finance Ltd | C20: 2026-03-13 08:13:00 | D20: 2026-03-13 14:13:00 | E20: Connectivity & Software | F20: Driver & Setup | G20: Medium | H20: James | I20: Network Team | J20: 6.6 | K20: 8 | L20: Yes | M20: 4 | N20: No | O20: Closed | P20: Fixed | Q20: East | R20: =IF(Table14[[#This Row],[Resolution_Time]]>Table14[[#This Row],[SLA_Target]],"No", "Yes") -> Yes | S20: =IF(Table14[[#This Row],[Calculated_SLA]]=Table14[[#This Row],[SLA_Met]],"Match","Mismatch") -> Match | T20: =IF(Table14[[#This Row],[Calculated_SLA]]="Yes",1,0) -> 1 | U20: =IF(COUNTIFS(Reference_data!A:A,Table14[[#This Row],[Category]],Reference_data!B:B,Table14[[#This Row],[Subcategory]])>0,"Valid","Invalid") -> Valid
A21: TKT000020 | B21: HDFC Bank Ltd | C21: 2026-01-07 12:07:00 | D21: 2026-01-07 17:07:00 | E21: Print Quality | F21: Defective Prints | G21: Medium | H21: James | I21: Remote Support | J21: 5.1 | K21: 8 | L21: Yes | M21: 4 | N21: No | O21: Closed | P21: Fixed | Q21: West | R21: =IF(Table14[[#This Row],[Resolution_Time]]>Table14[[#This Row],[SLA_Target]],"No", "Yes") -> Yes | S21: =IF(Table14[[#This Row],[Calculated_SLA]]=Table14[[#This Row],[SLA_Met]],"Match","Mismatch") -> Match | T21: =IF(Table14[[#This Row],[Calculated_SLA]]="Yes",1,0) -> 1 | U21: =IF(COUNTIFS(Reference_data!A:A,Table14[[#This Row],[Category]],Reference_data!B:B,Table14[[#This Row],[Subcategory]])>0,"Valid","Invalid") -> Valid
A22: TKT000021 | B22: Amazon Ltd | C22: 2026-01-17 13:17:00 | D22: 2026-01-17 22:17:00 | E22: Connectivity & Software | F22: Network Dropouts | G22: Low | H22: Emma | I22: Network Team | J22: 9.6 | K22: 24 | L22: Yes | M22: 4 | N22: No | O22: Closed | P22: Fixed | Q22: West | R22: =IF(Table14[[#This Row],[Resolution_Time]]>Table14[[#This Row],[SLA_Target]],"No", "Yes") -> Yes | S22: =IF(Table14[[#This Row],[Calculated_SLA]]=Table14[[#This Row],[SLA_Met]],"Match","Mismatch") -> Match | T22: =IF(Table14[[#This Row],[Calculated_SLA]]="Yes",1,0) -> 1 | U22: =IF(COUNTIFS(Reference_data!A:A,Table14[[#This Row],[Category]],Reference_data!B:B,Table14[[#This Row],[Subcategory]])>0,"Valid","Invalid") -> Valid
A23: TKT000022 | B23: Bajaj Finance Ltd | C23: 2026-02-21 11:21:00 | D23: 2026-02-21 18:21:00 | E23: Supplies & Logistics | F23: Paper Supply | G23: Low | H23: Judy | I23: Logistics Team | J23: 7.4 | K23: 24 | L23: Yes | M23: 5 | N23: No | O23: Closed | P23: Fixed | Q23: North | R23: =IF(Table14[[#This Row],[Resolution_Time]]>Table14[[#This Row],[SLA_Target]],"No", "Yes") -> Yes | S23: =IF(Table14[[#This Row],[Calculated_SLA]]=Table14[[#This Row],[SLA_Met]],"Match","Mismatch") -> Match | T23: =IF(Table14[[#This Row],[Calculated_SLA]]="Yes",1,0) -> 1 | U23: =IF(COUNTIFS(Reference_data!A:A,Table14[[#This Row],[Category]],Reference_data!B:B,Table14[[#This Row],[Subcategory]])>0,"Valid","Invalid") -> Valid
A24: TKT000023 | B24: Bharti Airtel Ltd | C24: 2026-02-12 11:12:00 | D24: 2026-02-12 20:12:00 | E24: Print Quality | F24: Color Calibration | G24: Medium | H24: Jack | I24: Remote Support | J24: 9.1 | K24: 8 | L24: No | M24: \N | N24: Yes | O24: Closed | P24: Temporary Workaround | Q24: East | R24: =IF(Table14[[#This Row],[Resolution_Time]]>Table14[[#This Row],[SLA_Target]],"No", "Yes") -> No | S24: =IF(Table14[[#This Row],[Calculated_SLA]]=Table14[[#This Row],[SLA_Met]],"Match","Mismatch") -> Match | T24: =IF(Table14[[#This Row],[Calculated_SLA]]="Yes",1,0) -> 0 | U24: =IF(COUNTIFS(Reference_data!A:A,Table14[[#This Row],[Category]],Reference_data!B:B,Table14[[#This Row],[Subcategory]])>0,"Valid","Invalid") -> Valid
A25: TKT000024 | B25: Bajaj Finance Ltd | C25: 2026-02-21 17:21:00 | D25: 2026-02-22 01:22:00 | E25: Print Quality | F25: Color Calibration | G25: Medium | H25: Tony | I25: Remote Support | J25: 8 | K25: 8 | L25: Yes | M25: 5 | N25: No | O25: Closed | P25: Fixed | Q25: South | R25: =IF(Table14[[#This Row],[Resolution_Time]]>Table14[[#This Row],[SLA_Target]],"No", "Yes") -> Yes | S25: =IF(Table14[[#This Row],[Calculated_SLA]]=Table14[[#This Row],[SLA_Met]],"Match","Mismatch") -> Match | T25: =IF(Table14[[#This Row],[Calculated_SLA]]="Yes",1,0) -> 1 | U25: =IF(COUNTIFS(Reference_data!A:A,Table14[[#This Row],[Category]],Reference_data!B:B,Table14[[#This Row],[Subcategory]])>0,"Valid","Invalid") -> Valid
A26: TKT000025 | B26: Amazon Ltd | C26: 2026-02-16 13:16:00 | D26: 2026-02-17 03:17:00 | E26: Connectivity & Software | F26: Scan-to-Email | G26: Medium | H26: James | I26: Network Team | J26: 14.7 | K26: 8 | L26: No | M26: 1 | N26: Yes | O26: Closed | P26: Temporary Workaround | Q26: East | R26: =IF(Table14[[#This Row],[Resolution_Time]]>Table14[[#This Row],[SLA_Target]],"No", "Yes") -> No | S26: =IF(Table14[[#This Row],[Calculated_SLA]]=Table14[[#This Row],[SLA_Met]],"Match","Mismatch") -> Match | T26: =IF(Table14[[#This Row],[Calculated_SLA]]="Yes",1,0) -> 0 | U26: =IF(COUNTIFS(Reference_data!A:A,Table14[[#This Row],[Category]],Reference_data!B:B,Table14[[#This Row],[Subcategory]])>0,"Valid","Invalid") -> Valid
A27: TKT000026 | B27: Bharti Airtel Ltd | C27: 2026-03-25 17:25:00 | D27: 2026-03-26 02:26:00 | E27: Supplies & Logistics | F27: Toner Replenishment | G27: Medium | H27: Tony | I27: Logistics Team | J27: 9.2 | K27: 8 | L27: No | M27: 3 | N27: No | O27: Closed | P27: Escalated | Q27: East | R27: =IF(Table14[[#This Row],[Resolution_Time]]>Table14[[#This Row],[SLA_Target]],"No", "Yes") -> No | S27: =IF(Table14[[#This Row],[Calculated_SLA]]=Table14[[#This Row],[SLA_Met]],"Match","Mismatch") -> Match | T27: =IF(Table14[[#This Row],[Calculated_SLA]]="Yes",1,0) -> 0 | U27: =IF(COUNTIFS(Reference_data!A:A,Table14[[#This Row],[Category]],Reference_data!B:B,Table14[[#This Row],[Subcategory]])>0,"Valid","Invalid") -> Valid
A28: TKT000027 | B28: Reliance Ltd | C28: 2026-03-18 14:18:00 | D28: 2026-03-18 21:18:00 | E28: Print Quality | F28: Color Calibration | G28: Low | H28: Sarah | I28: Remote Support | J28: 6.3 | K28: 24 | L28: Yes | M28: 4 | N28: No | O28: Closed | P28: Fixed | Q28: East | R28: =IF(Table14[[#This Row],[Resolution_Time]]>Table14[[#This Row],[SLA_Target]],"No", "Yes") -> Yes | S28: =IF(Table14[[#This Row],[Calculated_SLA]]=Table14[[#This Row],[SLA_Met]],"Match","Mismatch") -> Match | T28: =IF(Table14[[#This Row],[Calculated_SLA]]="Yes",1,0) -> 1 | U28: =IF(COUNTIFS(Reference_data!A:A,Table14[[#This Row],[Category]],Reference_data!B:B,Table14[[#This Row],[Subcategory]])>0,"Valid","Invalid") -> Valid
A29: TKT000028 | B29: Bharti Airtel Ltd | C29: 2026-01-14 16:14:00 | D29: 2026-01-15 01:15:00 | E29: Connectivity & Software | F29: Network Dropouts | G29: Medium | H29: Sarah | I29: Network Team | J29: 9.5 | K29: 8 | L29: No | M29: 3 | N29: Yes | O29: Closed | P29: Temporary Workaround | Q29: West | R29: =IF(Table14[[#This Row],[Resolution_Time]]>Table14[[#This Row],[SLA_Target]],"No", "Yes") -> No | S29: =IF(Table14[[#This Row],[Calculated_SLA]]=Table14[[#This Row],[SLA_Met]],"Match","Mismatch") -> Match | T29: =IF(Table14[[#This Row],[Calculated_SLA]]="Yes",1,0) -> 0 | U29: =IF(COUNTIFS(Reference_data!A:A,Table14[[#This Row],[Category]],Reference_data!B:B,Table14[[#This Row],[Subcategory]])>0,"Valid","Invalid") -> Valid
A30: TKT000029 | B30: Reliance Ltd | C30: 2026-03-03 13:03:00 | D30: 2026-03-04 02:04:00 | E30: Connectivity & Software | F30: Driver & Setup | G30: Low | H30: James | I30: Network Team | J30: 12.4 | K30: 24 | L30: No | M30: 3 | N30: Yes | O30: Closed | P30: Escalated | Q30: West | R30: =IF(Table14[[#This Row],[Resolution_Time]]>Table14[[#This Row],[SLA_Target]],"No", "Yes") -> Yes | S30: =IF(Table14[[#This Row],[Calculated_SLA]]=Table14[[#This Row],[SLA_Met]],"Match","Mismatch") -> Mismatch | T30: =IF(Table14[[#This Row],[Calculated_SLA]]="Yes",1,0) -> 1 | U30: =IF(COUNTIFS(Reference_data!A:A,Table14[[#This Row],[Category]],Reference_data!B:B,Table14[[#This Row],[Subcategory]])>0,"Valid","Invalid") -> Valid
A31: TKT000030 | B31: Tata Consultancy Services Ltd | C31: 2026-01-20 13:20:00 | D31: 2026-01-21 05:21:00 | E31: Hardware & Mechanical | F31: Device Errors | G31: Medium | H31: James | I31: Hardware Team | J31: 15.5 | K31: 8 | L31: No | M31: 1 | N31: No | O31: Closed | P31: Escalated | Q31: West | R31: =IF(Table14[[#This Row],[Resolution_Time]]>Table14[[#This Row],[SLA_Target]],"No", "Yes") -> No | S31: =IF(Table14[[#This Row],[Calculated_SLA]]=Table14[[#This Row],[SLA_Met]],"Match","Mismatch") -> Match | T31: =IF(Table14[[#This Row],[Calculated_SLA]]="Yes",1,0) -> 0 | U31: =IF(COUNTIFS(Reference_data!A:A,Table14[[#This Row],[Category]],Reference_data!B:B,Table14[[#This Row],[Subcategory]])>0,"Valid","Invalid") -> Valid
A32: TKT000031 | B32: Bharti Airtel Ltd | C32: 2026-03-11 09:11:00 | D32: 2026-03-11 14:11:00 | E32: Print Quality | F32: Defective Prints | G32: Medium | H32: Tony | I32: Remote Support | J32: 5.8 | K32: 8 | L32: Yes | M32: 4 | N32: No | O32: Closed | P32: Fixed | Q32: North | R32: =IF(Table14[[#This Row],[Resolution_Time]]>Table14[[#This Row],[SLA_Target]],"No", "Yes") -> Yes | S32: =IF(Table14[[#This Row],[Calculated_SLA]]=Table14[[#This Row],[SLA_Met]],"Match","Mismatch") -> Match | T32: =IF(Table14[[#This Row],[Calculated_SLA]]="Yes",1,0) -> 1 | U32: =IF(COUNTIFS(Reference_data!A:A,Table14[[#This Row],[Category]],Reference_data!B:B,Table14[[#This Row],[Subcategory]])>0,"Valid","Invalid") -> Valid
A33: TKT000032 | B33: Bajaj Finance Ltd | C33: 2026-03-13 15:13:00 | D33: 2026-03-14 09:14:00 | E33: Hardware & Mechanical | F33: Paper Jam | G33: Medium | H33: Jack | I33: Hardware Team | J33: 18.1 | K33: 8 | L33: No | M33: 2 | N33: Yes | O33: Closed | P33: Escalated | Q33: West | R33: =IF(Table14[[#This Row],[Resolution_Time]]>Table14[[#This Row],[SLA_Target]],"No", "Yes") -> No | S33: =IF(Table14[[#This Row],[Calculated_SLA]]=Table14[[#This Row],[SLA_Met]],"Match","Mismatch") -> Match | T33: =IF(Table14[[#This Row],[Calculated_SLA]]="Yes",1,0) -> 0 | U33: =IF(COUNTIFS(Reference_data!A:A,Table14[[#This Row],[Category]],Reference_data!B:B,Table14[[#This Row],[Subcategory]])>0,"Valid","Invalid") -> Valid
A34: TKT000033 | B34: Tata Consultancy Services Ltd | C34: 2026-01-11 15:11:00 | D34: 2026-01-12 02:12:00 | E34: Connectivity & Software | F34: Driver & Setup | G34: Low | H34: Mary | I34: Network Team | J34: 11.1 | K34: 24 | L34: Yes | M34: 5 | N34: No | O34: Closed | P34: Fixed | Q34: West | R34: =IF(Table14[[#This Row],[Resolution_Time]]>Table14[[#This Row],[SLA_Target]],"No", "Yes") -> Yes | S34: =IF(Table14[[#This Row],[Calculated_SLA]]=Table14[[#This Row],[SLA_Met]],"Match","Mismatch") -> Match | T34: =IF(Table14[[#This Row],[Calculated_SLA]]="Yes",1,0) -> 1 | U34: =IF(COUNTIFS(Reference_data!A:A,Table14[[#This Row],[Category]],Reference_data!B:B,Table14[[#This Row],[Subcategory]])>0,"Valid","Invalid") -> Valid
A35: TKT000034 | B35: United Overseas Bank | C35: 2026-03-26 14:26:00 | D35: 2026-03-26 20:26:00 | E35: Print Quality | F35: Finishing Errors | G35: High | H35: Tina | I35: Field Support | J35: 6.4 | K35: 4 | L35: No | M35: 3 | N35: No | O35: Closed | P35: Escalated | Q35: West | R35: =IF(Table14[[#This Row],[Resolution_Time]]>Table14[[#This Row],[SLA_Target]],"No", "Yes") -> No | S35: =IF(Table14[[#This Row],[Calculated_SLA]]=Table14[[#This Row],[SLA_Met]],"Match","Mismatch") -> Match | T35: =IF(Table14[[#This Row],[Calculated_SLA]]="Yes",1,0) -> 0 | U35: =IF(COUNTIFS(Reference_data!A:A,Table14[[#This Row],[Category]],Reference_data!B:B,Table14[[#This Row],[Subcategory]])>0,"Valid","Invalid") -> Valid
A36: TKT000035 | B36: United Overseas Bank | C36: 2026-02-12 08:12:00 | D36: 2026-02-12 17:12:00 | E36: Hardware & Mechanical | F36: Paper Jam | G36: Low | H36: James | I36: Hardware Team | J36: 9.6 | K36: 24 | L36: Yes | M36: 4 | N36: No | O36: Closed | P36: Fixed | Q36: East | R36: =IF(Table14[[#This Row],[Resolution_Time]]>Table14[[#This Row],[SLA_Target]],"No", "Yes") -> Yes | S36: =IF(Table14[[#This Row],[Calculated_SLA]]=Table14[[#This Row],[SLA_Met]],"Match","Mismatch") -> Match | T36: =IF(Table14[[#This Row],[Calculated_SLA]]="Yes",1,0) -> 1 | U36: =IF(COUNTIFS(Reference_data!A:A,Table14[[#This Row],[Category]],Reference_data!B:B,Table14[[#This Row],[Subcategory]])>0,"Valid","Invalid") -> Valid
... A38: TKT000037 | B38: HDFC Bank Ltd | C38: 2026-03-15 08:15:00 | D38: 2026-03-15 17:15:00 | E38: Connectivity & Software | F38: Scan-to-Email | G38: Medium | H38: Judy | I38: Network Team | J38: 8.6 | K38: 8 | L38: No | M38: 3 | N38: Yes | O38: Closed | P38: Escalated | Q38: East | R38: =IF(Table14[[#This Row],[Resolution_Time]]>Table14[[#This Row],[SLA_Target]],"No", "Yes") -> No | S38: =IF(Table14[[#This Row],[Calculated_SLA]]=Table14[[#This Row],[SLA_Met]],"Match","Mismatch") -> Match | T38: =IF(Table14[[#This Row],[Calculated_SLA]]="Yes",1,0) -> 0 | U38: =IF(COUNTIFS(Reference_data!A:A,Table14[[#This Row],[Category]],Reference_data!B:B,Table14[[#This Row],[Subcategory]])>0,"Valid","Invalid") -> Valid
A39: TKT000038 | B39: Tata Consultancy Services Ltd | C39: 2026-03-04 13:04:00 | D39: 2026-03-04 17:04:00 | E39: Print Quality | F39: Defective Prints | G39: Medium | H39: Emma | I39: Remote Support | J39: 4.1 | K39: 8 | L39: Yes | M39: \N | N39: No | O39: Closed | P39: Fixed | Q39: South | R39: =IF(Table14[[#This Row],[Resolution_Time]]>Table14[[#This Row],[SLA_Target]],"No", "Yes") -> Yes | S39: =IF(Table14[[#This Row],[Calculated_SLA]]=Table14[[#This Row],[SLA_Met]],"Match","Mismatch") -> Match | T39: =IF(Table14[[#This Row],[Calculated_SLA]]="Yes",1,0) -> 1 | U39: =IF(COUNTIFS(Reference_data!A:A,Table14[[#This Row],[Category]],Reference_data!B:B,Table14[[#This Row],[Subcategory]])>0,"Valid","Invalid") -> Valid
A40: TKT000039 | B40: Bajaj Finance Ltd | C40: 2026-02-27 08:27:00 | D40: 2026-02-27 17:27:00 | E40: Supplies & Logistics | F40: Toner Replenishment | G40: High | H40: Mary | I40: Logistics Team | J40: 8.8 | K40: 4 | L40: No | M40: 3 | N40: Yes | O40: Closed | P40: Temporary Workaround | Q40: North | R40: =IF(Table14[[#This Row],[Resolution_Time]]>Table14[[#This Row],[SLA_Target]],"No", "Yes") -> No | S40: =IF(Table14[[#This Row],[Calculated_SLA]]=Table14[[#This Row],[SLA_Met]],"Match","Mismatch") -> Match | T40: =IF(Table14[[#This Row],[Calculated_SLA]]="Yes",1,0) -> 0 | U40: =IF(COUNTIFS(Reference_data!A:A,Table14[[#This Row],[Category]],Reference_data!B:B,Table14[[#This Row],[Subcategory]])>0,"Valid","Invalid") -> Valid
A41: TKT000040 | B41: Hindustan Unilever Ltd | C41: 2026-01-27 14:27:00 | D41: 2026-01-27 23:27:00 | E41: Hardware & Mechanical | F41: Parts Wear | G41: Low | H41: Sarah | I41: Field Support | J41: 8.6 | K41: 24 | L41: Yes | M41: 4 | N41: No | O41: Closed | P41: Fixed | Q41: East | R41: =IF(Table14[[#This Row],[Resolution_Time]]>Table14[[#This Row],[SLA_Target]],"No", "Yes") -> Yes | S41: =IF(Table14[[#This Row],[Calculated_SLA]]=Table14[[#This Row],[SLA_Met]],"Match","Mismatch") -> Match | T41: =IF(Table14[[#This Row],[Calculated_SLA]]="Yes",1,0) -> 1 | U41: =IF(COUNTIFS(Reference_data!A:A,Table14[[#This Row],[Category]],Reference_data!B:B,Table14[[#This Row],[Subcategory]])>0,"Valid","Invalid") -> Valid
A42: TKT000041 | B42: HDFC Bank Ltd | C42: 2026-02-27 09:27:00 | D42: 2026-02-27 18:27:00 | E42: Hardware & Mechanical | F42: Paper Jam | G42: Medium | H42: Judy | I42: Hardware Team | J42: 9.8 | K42: 8 | L42: No | M42: 1 | N42: Yes | O42: Closed | P42: Escalated | Q42: North | R42: =IF(Table14[[#This Row],[Resolution_Time]]>Table14[[#This Row],[SLA_Target]],"No", "Yes") -> No | S42: =IF(Table14[[#This Row],[Calculated_SLA]]=Table14[[#This Row],[SLA_Met]],"Match","Mismatch") -> Match | T42: =IF(Table14[[#This Row],[Calculated_SLA]]="Yes",1,0) -> 0 | U42: =IF(COUNTIFS(Reference_data!A:A,Table14[[#This Row],[Category]],Reference_data!B:B,Table14[[#This Row],[Subcategory]])>0,"Valid","Invalid") -> Valid
A43: TKT000042 | B43: Amazon Ltd | C43: 2026-03-21 08:21:00 | D43: 2026-03-21 20:21:00 | E43: Print Quality | F43: Defective Prints | G43: Medium | H43: Mary | I43: Remote Support | J43: 12.3 | K43: 8 | L43: No | M43: 1 | N43: Yes | O43: Closed | P43: Escalated | Q43: West | R43: =IF(Table14[[#This Row],[Resolution_Time]]>Table14[[#This Row],[SLA_Target]],"No", "Yes") -> No | S43: =IF(Table14[[#This Row],[Calculated_SLA]]=Table14[[#This Row],[SLA_Met]],"Match","Mismatch") -> Match | T43: =IF(Table14[[#This Row],[Calculated_SLA]]="Yes",1,0) -> 0 | U43: =IF(COUNTIFS(Reference_data!A:A,Table14[[#This Row],[Category]],Reference_data!B:B,Table14[[#This Row],[Subcategory]])>0,"Valid","Invalid") -> Valid
A44: TKT000043 | B44: Reliance Ltd | C44: 2026-01-17 09:17:00 | D44: 2026-01-17 19:17:00 | E44: Connectivity & Software | F44: Scan-to-Email | G44: Medium | H44: Tony | I44: Network Team | J44: 10.7 | K44: 8 | L44: No | M44: 1 | N44: No | O44: Closed | P44: Escalated | Q44: West | R44: =IF(Table14[[#This Row],[Resolution_Time]]>Table14[[#This Row],[SLA_Target]],"No", "Yes") -> No | S44: =IF(Table14[[#This Row],[Calculated_SLA]]=Table14[[#This Row],[SLA_Met]],"Match","Mismatch") -> Match | T44: =IF(Table14[[#This Row],[Calculated_SLA]]="Yes",1,0) -> 0 | U44: =IF(COUNTIFS(Reference_data!A:A,Table14[[#This Row],[Category]],Reference_data!B:B,Table14[[#This Row],[Subcategory]])>0,"Valid","Invalid") -> Valid
A45: TKT000044 | B45: Reliance Ltd | C45: 2026-01-12 11:12:00 | D45: 2026-01-12 16:12:00 | E45: Print Quality | F45: Finishing Errors | G45: Medium | H45: Tony | I45: Field Support | J45: 4.9 | K45: 8 | L45: Yes | M45: 4 | N45: No | O45: Closed | P45: Fixed | Q45: East | R45: =IF(Table14[[#This Row],[Resolution_Time]]>Table14[[#This Row],[SLA_Target]],"No", "Yes") -> Yes | S45: =IF(Table14[[#This Row],[Calculated_SLA]]=Table14[[#This Row],[SLA_Met]],"Match","Mismatch") -> Match | T45: =IF(Table14[[#This Row],[Calculated_SLA]]="Yes",1,0) -> 1 | U45: =IF(COUNTIFS(Reference_data!A:A,Table14[[#This Row],[Category]],Reference_data!B:B,Table14[[#This Row],[Subcategory]])>0,"Valid","Invalid") -> Valid
...

Sheet Reference_data
A1: Category | B1: Sub Category | C1: Department
A2: Hardware & Mechanical | B2: Paper Jam | C2: Hardware Team
A3: Hardware & Mechanical | B3: Device Errors | C3: Hardware Team
A4: Hardware & Mechanical | B4: Parts Wear | C4: Field Support
A5: Print Quality | B5: Defective Prints | C5: Remote Support
A6: Print Quality | B6: Color Calibration | C6: Remote Support
A7: Print Quality | B7: Finishing Errors | C7: Field Support
A8: Connectivity & Software | B8: Network Dropouts | C8: Network Team
A9: Connectivity & Software | B9: Driver & Setup | C9: Network Team
A10: Connectivity & Software | B10: Scan-to-Email | C10: Network Team
A11: Supplies & Logistics | B11: Toner Replenishment | C11: Logistics Team
A12: Supplies & Logistics | B12: Paper Supply | C12: Logistics Team
... A14: Contract & Billing | B14: Relocation Requests | C14: Billing Team

Sheet Raw Data
A1: Ticket_ID | B1: Account | C1: Created_Date | D1: Closed_Date | E1: Category | F1: Sub_Category | G1: Priority | H1: Agent | I1: Department | J1: Resolution_Time_Hrs | K1: SLA_Target_Hrs | L1: SLA_Met | M1: Customer_Rating | N1: Reopened | O1: Ticket_Status | P1: Resolution_Type | Q1: Region
A2: TKT000001 | B2: United Overseas Bank | C2: 03/17/2026 16:23 | D2: 03/18/2026 07:35 | E2: Connectivity & Software | F2: Network Dropouts | G2: Low | H2: Michael | I2: Network Team | J2: 15.2 | K2: 24 | L2: Yes | M2: 4 | N2: No | O2: Closed | P2: Fixed | Q2: South
A3: TKT000002 | B3: Amazon Ltd | C3: 03/21/2026 13:21 | D3: 03/21/2026 18:21 | E3: Print Quality | F3: Finishing Errors | G3: Low | H3: Tina | I3: Field Support | J3: 5 | K3: 24 | L3: No | M3: 3 | N3: Yes | O3: Closed | P3: Temporary Workaround | Q3: West
A4: TKT000003 | B4: Tata Consultancy Services Ltd | C4: 03/25/2026 14:44 | D4: 03/25/2026 18:02 | E4: Contract & Billing | F4: Relocation Requests | G4: Medium | H4: Emma | I4: Billing Team | J4: 3.3 | K4: 8 | L4: Yes | M4: 4 | N4: No | O4: Closed | P4: Fixed | Q4: South
A5: TKT000004 | B5: HDFC Bank Ltd | C5: 03/22/2026 08:20 | D5: 03/22/2026 15:14 | E5: Print Quality | F5: Color Calibration | G5: High | H5: James | I5: Remote Support | J5: 6.9 | K5: 4 | L5: No | M5: 1 | N5: No | O5: Closed | P5: Escalated | Q5: North
A6: TKT000005 | B6: ICICI Bank Ltd | C6: 01/27/2026 12:34 | D6: 01/27/2026 22:40 | E6: Connectivity & Software | F6: Driver & Setup | G6: Medium | H6: Sarah | I6: Network Team | J6: 10.1 | K6: 8 | L6: No | M6: 1 | N6: No | O6: Closed | P6: Temporary Workaround | Q6: North
A7: TKT000006 | B7: LIC Corp Ltd | C7: 01/17/2026 11:58 | D7: 01/17/2026 23:58 | E7: Connectivity & Software | F7: Scan-to-Email | G7: Medium | H7: Judy | I7: Network Team | J7: 12 | K7: 8 | L7: No | M7: 3 | N7: No | O7: Closed | P7: Escalated | Q7: West
A8: TKT000007 | B8: Amazon Ltd | C8: 03/17/2026 13:05 | D8: 03/17/2026 17:59 | E8: Connectivity & Software | F8: Scan-to-Email | G8: Medium | H8: Emma | I8: Network Team | J8: 4.9 | K8: 8 | L8: Yes | M8: 4 | N8: No | O8: Closed | P8: Fixed | Q8: West
A9: TKT000008 | B9: Reliance Ltd | C9: 03/20/2026 14:09 | D9: 03/21/2026 03:39 | E9: Hardware & Mechanical | F9: Device Errors | G9: Medium | H9: Judy | I9: Hardware Team | J9: 13.5 | K9: 8 | L9: No | M9: 1 | N9: No | O9: Closed | P9: Temporary Workaround | Q9: West
A10: TKT000009 | B10: Amazon Ltd | C10: 03/17/2026 13:30 | D10: 03/17/2026 23:00 | E10: Supplies & Logistics | F10: Paper Supply | G10: Medium | H10: Mary | I10: Logistics Team | J10: 9.5 | K10: 8 | L10: No | M10: 3 | N10: No | O10: Closed | P10: Temporary Workaround | Q10: West
A11: TKT000010 | B11: Amazon Ltd | C11: 02/09/2026 13:38 | D11: 02/10/2026 04:26 | E11: Connectivity & Software | F11: Network Dropouts | G11: High | H11: Tony | I11: Network Team | J11: 14.8 | K11: 4 | L11: No | M11: 2 | N11: No | O11: Closed | P11: Escalated | Q11: North
A12: TKT000011 | B12: HDFC Bank Ltd | C12: 03/09/2026 13:05 | D12: 03/10/2026 03:35 | E12: Hardware & Mechanical | F12: Device Errors | G12: Low | H12: Mary | I12: Hardware Team | J12: 14.5 | K12: 24 | L12: Yes | M12: 4 | N12: No | O12: Closed | P12: Fixed | Q12: West
A13: TKT000012 | B13: Amazon Ltd | C13: 03/05/2026 16:21 | D13: 03/06/2026 05:09 | E13: Connectivity & Software | F13: Network Dropouts | G13: Medium | H13: James | I13: Network Team | J13: 12.8 | K13: 8 | L13: No | M13: 2 | N13: No | O13: Closed | P13: Escalated | Q13: West
... A18: TKT000017 | B18: HDFC Bank Ltd | C18: 02/15/2026 15:34 | D18: 02/15/2026 20:46 | E18: Supplies & Logistics | F18: Toner Replenishment | G18: Medium | H18: Judy | I18: Logistics Team | J18: 5.2 | K18: 8 | L18: Yes | M18: 4 | N18: No | O18: Closed | P18: Fixed | Q18: North
A19: TKT000018 | B19: HDFC Bank Ltd | C19: 01/06/2026 12:05 | D19: 01/06/2026 21:17 | E19: Hardware & Mechanical | F19: Device Errors | G19: Medium | H19: Sarah | I19: Hardware Team | J19: 9.2 | K19: 8 | L19: No | N19: Yes | O19: Closed | P19: Escalated | Q19: West
A20: TKT000019 | B20: Bajaj Finance Ltd | C20: 03/13/2026 08:19 | D20: 03/13/2026 14:55 | E20: Connectivity & Software | F20: Driver & Setup | G20: Medium | H20: James | I20: Network Team | J20: 6.6 | K20: 8 | L20: Yes | M20: 4 | N20: No | O20: Closed | P20: Fixed | Q20: East
A21: TKT000020 | B21: HDFC Bank Ltd | C21: 01/07/2026 12:12 | D21: 01/07/2026 17:18 | E21: Print Quality | F21: Defective Prints | G21: Medium | H21: James | I21: Remote Support | J21: 5.1 | K21: 8 | L21: Yes | M21: 4 | N21: No | O21: Closed | P21: Fixed | Q21: West
A22: TKT000021 | B22: Amazon Ltd | C22: 01/17/2026 13:16 | D22: 01/17/2026 22:52 | E22: Connectivity & Software | F22: Network Dropouts | G22: Low | H22: Emma | I22: Network Team | J22: 9.6 | K22: 24 | L22: Yes | M22: 4 | N22: No | O22: Closed | P22: Fixed | Q22: West
A23: TKT000022 | B23: Bajaj Finance Ltd | C23: 02/21/2026 11:24 | D23: 02/21/2026 18:48 | E23: Supplies & Logistics | F23: Paper Supply | G23: Low | H23: Judy | I23: Logistics Team | J23: 7.4 | K23: 24 | L23: Yes | M23: 5 | N23: No | O23: Closed | P23: Fixed | Q23: North
A24: TKT000023 | B24: Bharti Airtel Ltd | C24: 02/12/2026 11:08 | D24: 02/12/2026 20:14 | E24: Print Quality | F24: Color Calibration | G24: Medium | H24: Jack | I24: Remote Support | J24: 9.1 | K24: 8 | L24: No | N24: Yes | O24: Closed | P24: Temporary Workaround | Q24: East
A25: TKT000024 | B25: Bajaj Finance Ltd | C25: 02/21/2026 17:41 | D25: 02/22/2026 01:41 | E25: Print Quality | F25: Color Calibration | G25: Medium | H25: Tony | I25: Remote Support | J25: 8 | K25: 8 | L25: Yes | M25: 5 | N25: No | O25: Closed | P25: Fixed | Q25: South
A26: TKT000025 | B26: Amazon Ltd | C26: 02/16/2026 13:05 | D26: 02/17/2026 03:47 | E26: Connectivity & Software | F26: Scan-to-Email | G26: Medium | H26: James | I26: Network Team | J26: 14.7 | K26: 8 | L26: No | M26: 1 | N26: Yes | O26: Closed | P26: Temporary Workaround | Q26: East
A27: TKT000026 | B27: Bharti Airtel Ltd | C27: 03/25/2026 17:10 | D27: 03/26/2026 02:22 | E27: Supplies & Logistics | F27: Toner Replenishment | G27: Medium | H27: Tony | I27: Logistics Team | J27: 9.2 | K27: 8 | L27: No | M27: 3 | N27: No | O27: Closed | P27: Escalated | Q27: East
A28: TKT000027 | B28: Reliance Ltd | C28: 03/18/2026 14:55 | D28: 03/18/2026 21:13 | E28: Print Quality | F28: Color Calibration | G28: Low | H28: Sarah | I28: Remote Support | J28: 6.3 | K28: 24 | L28: Yes | M28: 4 | N28: No | O28: Closed | P28: Fixed | Q28: East
A29: TKT000028 | B29: Bharti Airtel Ltd | C29: 01/14/2026 16:06 | D29: 01/15/2026 01:36 | E29: Connectivity & Software | F29: Network Dropouts | G29: Medium | H29: Sarah | I29: Network Team | J29: 9.5 | K29: 8 | L29: No | M29: 3 | N29: Yes | O29: Closed | P29: Temporary Workaround | Q29: West
A30: TKT000029 | B30: Reliance Ltd | C30: 03/03/2026 13:49 | D30: 03/04/2026 02:13 | E30: Connectivity & Software | F30: Driver & Setup | G30: Low | H30: James | I30: Network Team | J30: 12.4 | K30: 24 | L30: No | M30: 3 | N30: Yes | O30: Closed | P30: Escalated | Q30: West
A31: TKT000030 | B31: Tata Consultancy Services Ltd | C31: 01/20/2026 13:57 | D31: 01/21/2026 05:27 | E31: Hardware & Mechanical | F31: Device Errors | G31: Medium | H31: James | I31: Hardware Team | J31: 15.5 | K31: 8 | L31: No | M31: 1 | N31: No | O31: Closed | P31: Escalated | Q31: West
A32: TKT000031 | B32: Bharti Airtel Ltd | C32: 03/11/2026 09:08 | D32: 03/11/2026 14:56 | E32: Print Quality | F32: Defective Prints | G32: Medium | H32: Tony | I32: Remote Support | J32: 5.8 | K32: 8 | L32: Yes | M32: 4 | N32: No | O32: Closed | P32: Fixed | Q32: North
A33: TKT000032 | B33: Bajaj Finance Ltd | C33: 03/13/2026 15:33 | D33: 03/14/2026 09:39 | E33: Hardware & Mechanical | F33: Paper Jam | G33: Medium | H33: Jack | I33: Hardware Team | J33: 18.1 | K33: 8 | L33: No | M33: 2 | N33: Yes | O33: Closed | P33: Escalated | Q33: West
A34: TKT000033 | B34: Tata Consultancy Services Ltd | C34: 01/11/2026 15:33 | D34: 01/12/2026 02:39 | E34: Connectivity & Software | F34: Driver & Setup | G34: Low | H34: Mary | I34: Network Team | J34: 11.1 | K34: 24 | L34: Yes | M34: 5 | N34: No | O34: Closed | P34: Fixed | Q34: West
A35: TKT000034 | B35: United Overseas Bank | C35: 03/26/2026 14:31 | D35: 03/26/2026 20:55 | E35: Print Quality | F35: Finishing Errors | G35: High | H35: Tina | I35: Field Support | J35: 6.4 | K35: 4 | L35: No | M35: 3 | N35: No | O35: Closed | P35: Escalated | Q35: West
A36: TKT000035 | B36: United Overseas Bank | C36: 02/12/2026 08:13 | D36: 02/12/2026 17:49 | E36: Hardware & Mechanical | F36: Paper Jam | G36: Low | H36: James | I36: Hardware Team | J36: 9.6 | K36: 24 | L36: Yes | M36: 4 | N36: No | O36: Closed | P36: Fixed | Q36: East
... A38: TKT000037 | B38: HDFC Bank Ltd | C38: 03/15/2026 08:38 | D38: 03/15/2026 17:14 | E38: Connectivity & Software | F38: Scan-to-Email | G38: Medium | H38: Judy | I38: Network Team | J38: 8.6 | K38: 8 | L38: No | M38: 3 | N38: Yes | O38: Closed | P38: Escalated | Q38: East
A39: TKT000038 | B39: Tata Consultancy Services Ltd | C39: 03/04/2026 13:04 | D39: 03/04/2026 17:10 | E39: Print Quality | F39: Defective Prints | G39: Medium | H39: Emma | I39: Remote Support | J39: 4.1 | K39: 8 | L39: Yes | N39: No | O39: Closed | P39: Fixed | Q39: South
A40: TKT000039 | B40: Bajaj Finance Ltd | C40: 02/27/2026 08:34 | D40: 02/27/2026 17:22 | E40: Supplies & Logistics | F40: Toner Replenishment | G40: High | H40: Mary | I40: Logistics Team | J40: 8.8 | K40: 4 | L40: No | M40: 3 | N40: Yes | O40: Closed | P40: Temporary Workaround | Q40: North
A41: TKT000040 | B41: Hindustan Unilever Ltd | C41: 01/27/2026 14:30 | D41: 01/27/2026 23:06 | E41: Hardware & Mechanical | F41: Parts Wear | G41: Low | H41: Sarah | I41: Field Support | J41: 8.6 | K41: 24 | L41: Yes | M41: 4 | N41: No | O41: Closed | P41: Fixed | Q41: East
A42: TKT000041 | B42: HDFC Bank Ltd | C42: 02/27/2026 09:00 | D42: 02/27/2026 18:48 | E42: Hardware & Mechanical | F42: Paper Jam | G42: Medium | H42: Judy | I42: Hardware Team | J42: 9.8 | K42: 8 | L42: No | M42: 1 | N42: Yes | O42: Closed | P42: Escalated | Q42: North
A43: TKT000042 | B43: Amazon Ltd | C43: 03/21/2026 08:14 | D43: 03/21/2026 20:32 | E43: Print Quality | F43: Defective Prints | G43: Medium | H43: Mary | I43: Remote Support | J43: 12.3 | K43: 8 | L43: No | M43: 1 | N43: Yes | O43: Closed | P43: Escalated | Q43: West
A44: TKT000043 | B44: Reliance Ltd | C44: 01/17/2026 09:06 | D44: 01/17/2026 19:48 | E44: Connectivity & Software | F44: Scan-to-Email | G44: Medium | H44: Tony | I44: Network Team | J44: 10.7 | K44: 8 | L44: No | M44: 1 | N44: No | O44: Closed | P44: Escalated | Q44: West
A45: TKT000044 | B45: Reliance Ltd | C45: 01/12/2026 11:43 | D45: 01/12/2026 16:37 | E45: Print Quality | F45: Finishing Errors | G45: Medium | H45: Tony | I45: Field Support | J45: 4.9 | K45: 8 | L45: Yes | M45: 4 | N45: No | O45: Closed | P45: Fixed | Q45: East
...

Sheet Data Cleaned
A1: Ticket_ID | B1: Account | C1: Created_Date | D1: Closed_Date | E1: Category | F1: Sub_Category | G1: Priority | H1: Agent | I1: Department | J1: Resolution_Time_Hrs | K1: SLA_Target_Hrs | L1: SLA_Met | M1: Customer_Rating | N1: Reopened | O1: Ticket_Status | P1: Resolution_Type | Q1: Region | R1: Calculated_SLA | S1: SLA_Mismatch | T1: SLA_Score | U1: Sub_Category_Validation | V1: Expected_Category | W1: Category_Match
A2: TKT000001 | B2: United Overseas Bank | C2: 03/17/2026 16:23 | D2: 03/18/2026 07:35 | E2: Connectivity & Software | F2: Network Dropouts | G2: Low | H2: Michael | I2: Network Team | J2: 15.2 | K2: 24 | L2: Yes | M2: 4 | N2: No | O2: Closed | P2: Fixed | Q2: South | R2: =IF(Table1[[#This Row],[Resolution_Time_Hrs]]>Table1[[#This Row],[SLA_Target_Hrs]],"No", "Yes") -> Yes | S2: =IF(Table1[[#This Row],[Calculated_SLA]]=Table1[[#This Row],[SLA_Met]],"Match","Mismatch") -> Match | T2: =IF(Table1[[#This Row],[Calculated_SLA]]="Yes",1,0) -> 1 | U2: =IF(COUNTIFS(Reference_data!A:A,Table1[[#This Row],[Category]],Reference_data!B:B,Table1[[#This Row],[Sub_Category]])>0,"Valid","Invalid") -> Valid | V2: =_xlfn.XLOOKUP([1]!Table1[[#This Row],[Sub_Category]],[1]Reference_data!B:B,[1]Reference_data!A:A) -> Connectivity & Software | W2: =IF([1]!Table1[[#This Row],[Category]]=[1]!Table1[[#This Row],[Expected_Category ]],"Valid", "invalid") -> Valid
A3: TKT000002 | B3: Amazon Ltd | C3: 03/21/2026 13:21 | D3: 03/21/2026 18:21 | E3: Print Quality | F3: Finishing Errors | G3: Low | H3: Tina | I3: Field Support | J3: 5 | K3: 24 | L3: No | M3: 3 | N3: Yes | O3: Closed | P3: Temporary Workaround | Q3: West | R3: =IF(Table1[[#This Row],[Resolution_Time_Hrs]]>Table1[[#This Row],[SLA_Target_Hrs]],"No", "Yes") -> Yes | S3: =IF(Table1[[#This Row],[Calculated_SLA]]=Table1[[#This Row],[SLA_Met]],"Match","Mismatch") -> Mismatch | T3: =IF(Table1[[#This Row],[Calculated_SLA]]="Yes",1,0) -> 1 | U3: =IF(COUNTIFS(Reference_data!A:A,Table1[[#This Row],[Category]],Reference_data!B:B,Table1[[#This Row],[Sub_Category]])>0,"Valid","Invalid") -> Valid | V3: =_xlfn.XLOOKUP([1]!Table1[[#This Row],[Sub_Category]],[1]Reference_data!B:B,[1]Reference_data!A:A) -> Print Quality | W3: =IF([1]!Table1[[#This Row],[Category]]=[1]!Table1[[#This Row],[Expected_Category ]],"Valid", "invalid") -> Valid
A4: TKT000003 | B4: Tata Consultancy Services Ltd | C4: 03/25/2026 14:44 | D4: 03/25/2026 18:02 | E4: Contract & Billing | F4: Relocation Requests | G4: Medium | H4: Emma | I4: Billing Team | J4: 3.3 | K4: 8 | L4: Yes | M4: 4 | N4: No | O4: Closed | P4: Fixed | Q4: South | R4: =IF(Table1[[#This Row],[Resolution_Time_Hrs]]>Table1[[#This Row],[SLA_Target_Hrs]],"No", "Yes") -> Yes | S4: =IF(Table1[[#This Row],[Calculated_SLA]]=Table1[[#This Row],[SLA_Met]],"Match","Mismatch") -> Match | T4: =IF(Table1[[#This Row],[Calculated_SLA]]="Yes",1,0) -> 1 | U4: =IF(COUNTIFS(Reference_data!A:A,Table1[[#This Row],[Category]],Reference_data!B:B,Table1[[#This Row],[Sub_Category]])>0,"Valid","Invalid") -> Valid | V4: =_xlfn.XLOOKUP([1]!Table1[[#This Row],[Sub_Category]],[1]Reference_data!B:B,[1]Reference_data!A:A) -> Contract & Billing | W4: =IF([1]!Table1[[#This Row],[Category]]=[1]!Table1[[#This Row],[Expected_Category ]],"Valid", "invalid") -> Valid
A5: TKT000004 | B5: HDFC Bank Ltd | C5: 03/22/2026 08:20 | D5: 03/22/2026 15:14 | E5: Print Quality | F5: Color Calibration | G5: High | H5: James | I5: Remote Support | J5: 6.9 | K5: 4 | L5: No | M5: 1 | N5: No | O5: Closed | P5: Escalated | Q5: North | R5: =IF(Table1[[#This Row],[Resolution_Time_Hrs]]>Table1[[#This Row],[SLA_Target_Hrs]],"No", "Yes") -> No | S5: =IF(Table1[[#This Row],[Calculated_SLA]]=Table1[[#This Row],[SLA_Met]],"Match","Mismatch") -> Match | T5: =IF(Table1[[#This Row],[Calculated_SLA]]="Yes",1,0) -> 0 | U5: =IF(COUNTIFS(Reference_data!A:A,Table1[[#This Row],[Category]],Reference_data!B:B,Table1[[#This Row],[Sub_Category]])>0,"Valid","Invalid") -> Valid | V5: =_xlfn.XLOOKUP([1]!Table1[[#This Row],[Sub_Category]],[1]Reference_data!B:B,[1]Reference_data!A:A) -> Print Quality | W5: =IF([1]!Table1[[#This Row],[Category]]=[1]!Table1[[#This Row],[Expected_Category ]],"Valid", "invalid") -> Valid
A6: TKT000005 | B6: ICICI Bank Ltd | C6: 01/27/2026 12:34 | D6: 01/27/2026 22:40 | E6: Connectivity & Software | F6: Driver & Setup | G6: Medium | H6: Sarah | I6: Network Team | J6: 10.1 | K6: 8 | L6: No | M6: 1 | N6: No | O6: Closed | P6: Temporary Workaround | Q6: North | R6: =IF(Table1[[#This Row],[Resolution_Time_Hrs]]>Table1[[#This Row],[SLA_Target_Hrs]],"No", "Yes") -> No | S6: =IF(Table1[[#This Row],[Calculated_SLA]]=Table1[[#This Row],[SLA_Met]],"Match","Mismatch") -> Match | T6: =IF(Table1[[#This Row],[Calculated_SLA]]="Yes",1,0) -> 0 | U6: =IF(COUNTIFS(Reference_data!A:A,Table1[[#This Row],[Category]],Reference_data!B:B,Table1[[#This Row],[Sub_Category]])>0,"Valid","Invalid") -> Valid | V6: =_xlfn.XLOOKUP([1]!Table1[[#This Row],[Sub_Category]],[1]Reference_data!B:B,[1]Reference_data!A:A) -> Connectivity & Software | W6: =IF([1]!Table1[[#This Row],[Category]]=[1]!Table1[[#This Row],[Expected_Category ]],"Valid", "invalid") -> Valid
A7: TKT000006 | B7: LIC Corp Ltd | C7: 01/17/2026 11:58 | D7: 01/17/2026 23:58 | E7: Connectivity & Software | F7: Scan-to-Email | G7: Medium | H7: Judy | I7: Network Team | J7: 12 | K7: 8 | L7: No | M7: 3 | N7: No | O7: Closed | P7: Escalated | Q7: West | R7: =IF(Table1[[#This Row],[Resolution_Time_Hrs]]>Table1[[#This Row],[SLA_Target_Hrs]],"No", "Yes") -> No | S7: =IF(Table1[[#This Row],[Calculated_SLA]]=Table1[[#This Row],[SLA_Met]],"Match","Mismatch") -> Match | T7: =IF(Table1[[#This Row],[Calculated_SLA]]="Yes",1,0) -> 0 | U7: =IF(COUNTIFS(Reference_data!A:A,Table1[[#This Row],[Category]],Reference_data!B:B,Table1[[#This Row],[Sub_Category]])>0,"Valid","Invalid") -> Valid | V7: =_xlfn.XLOOKUP([1]!Table1[[#This Row],[Sub_Category]],[1]Reference_data!B:B,[1]Reference_data!A:A) -> Connectivity & Software | W7: =IF([1]!Table1[[#This Row],[Category]]=[1]!Table1[[#This Row],[Expected_Category ]],"Valid", "invalid") -> Valid
A8: TKT000007 | B8: Amazon Ltd | C8: 03/17/2026 13:05 | D8: 03/17/2026 17:59 | E8: Connectivity & Software | F8: Scan-to-Email | G8: Medium | H8: Emma | I8: Network Team | J8: 4.9 | K8: 8 | L8: Yes | M8: 4 | N8: No | O8: Closed | P8: Fixed | Q8: West | R8: =IF(Table1[[#This Row],[Resolution_Time_Hrs]]>Table1[[#This Row],[SLA_Target_Hrs]],"No", "Yes") -> Yes | S8: =IF(Table1[[#This Row],[Calculated_SLA]]=Table1[[#This Row],[SLA_Met]],"Match","Mismatch") -> Match | T8: =IF(Table1[[#This Row],[Calculated_SLA]]="Yes",1,0) -> 1 | U8: =IF(COUNTIFS(Reference_data!A:A,Table1[[#This Row],[Category]],Reference_data!B:B,Table1[[#This Row],[Sub_Category]])>0,"Valid","Invalid") -> Valid | V8: =_xlfn.XLOOKUP([1]!Table1[[#This Row],[Sub_Category]],[1]Reference_data!B:B,[1]Reference_data!A:A) -> Connectivity & Software | W8: =IF([1]!Table1[[#This Row],[Category]]=[1]!Table1[[#This Row],[Expected_Category ]],"Valid", "invalid") -> Valid
A9: TKT000008 | B9: Reliance Ltd | C9: 03/20/2026 14:09 | D9: 03/21/2026 03:39 | E9: Hardware & Mechanical | F9: Device Errors | G9: Medium | H9: Judy | I9: Hardware Team | J9: 13.5 | K9: 8 | L9: No | M9: 1 | N9: No | O9: Closed | P9: Temporary Workaround | Q9: West | R9: =IF(Table1[[#This Row],[Resolution_Time_Hrs]]>Table1[[#This Row],[SLA_Target_Hrs]],"No", "Yes") -> No | S9: =IF(Table1[[#This Row],[Calculated_SLA]]=Table1[[#This Row],[SLA_Met]],"Match","Mismatch") -> Match | T9: =IF(Table1[[#This Row],[Calculated_SLA]]="Yes",1,0) -> 0 | U9: =IF(COUNTIFS(Reference_data!A:A,Table1[[#This Row],[Category]],Reference_data!B:B,Table1[[#This Row],[Sub_Category]])>0,"Valid","Invalid") -> Valid | V9: =_xlfn.XLOOKUP([1]!Table1[[#This Row],[Sub_Category]],[1]Reference_data!B:B,[1]Reference_data!A:A) -> Hardware & Mechanical | W9: =IF([1]!Table1[[#This Row],[Category]]=[1]!Table1[[#This Row],[Expected_Category ]],"Valid", "invalid") -> Valid
A10: TKT000009 | B10: Amazon Ltd | C10: 03/17/2026 13:30 | D10: 03/17/2026 23:00 | E10: Supplies & Logistics | F10: Paper Supply | G10: Medium | H10: Mary | I10: Logistics Team | J10: 9.5 | K10: 8 | L10: No | M10: 3 | N10: No | O10: Closed | P10: Temporary Workaround | Q10: West | R10: =IF(Table1[[#This Row],[Resolution_Time_Hrs]]>Table1[[#This Row],[SLA_Target_Hrs]],"No", "Yes") -> No | S10: =IF(Table1[[#This Row],[Calculated_SLA]]=Table1[[#This Row],[SLA_Met]],"Match","Mismatch") -> Match | T10: =IF(Table1[[#This Row],[Calculated_SLA]]="Yes",1,0) -> 0 | U10: =IF(COUNTIFS(Reference_data!A:A,Table1[[#This Row],[Category]],Reference_data!B:B,Table1[[#This Row],[Sub_Category]])>0,"Valid","Invalid") -> Valid | V10: =_xlfn.XLOOKUP([1]!Table1[[#This Row],[Sub_Category]],[1]Reference_data!B:B,[1]Reference_data!A:A) -> Supplies & Logistics | W10: =IF([1]!Table1[[#This Row],[Category]]=[1]!Table1[[#This Row],[Expected_Category ]],"Valid", "invalid") -> Valid
A11: TKT000010 | B11: Amazon Ltd | C11: 02/09/2026 13:38 | D11: 02/10/2026 04:26 | E11: Connectivity & Software | F11: Network Dropouts | G11: High | H11: Tony | I11: Network Team | J11: 14.8 | K11: 4 | L11: No | M11: 2 | N11: No | O11: Closed | P11: Escalated | Q11: North | R11: =IF(Table1[[#This Row],[Resolution_Time_Hrs]]>Table1[[#This Row],[SLA_Target_Hrs]],"No", "Yes") -> No | S11: =IF(Table1[[#This Row],[Calculated_SLA]]=Table1[[#This Row],[SLA_Met]],"Match","Mismatch") -> Match | T11: =IF(Table1[[#This Row],[Calculated_SLA]]="Yes",1,0) -> 0 | U11: =IF(COUNTIFS(Reference_data!A:A,Table1[[#This Row],[Category]],Reference_data!B:B,Table1[[#This Row],[Sub_Category]])>0,"Valid","Invalid") -> Valid | V11: =_xlfn.XLOOKUP([1]!Table1[[#This Row],[Sub_Category]],[1]Reference_data!B:B,[1]Reference_data!A:A) -> Connectivity & Software | W11: =IF([1]!Table1[[#This Row],[Category]]=[1]!Table1[[#This Row],[Expected_Category ]],"Valid", "invalid") -> Valid
A12: TKT000011 | B12: HDFC Bank Ltd | C12: 03/09/2026 13:05 | D12: 03/10/2026 03:35 | E12: Hardware & Mechanical | F12: Device Errors | G12: Low | H12: Mary | I12: Hardware Team | J12: 14.5 | K12: 24 | L12: Yes | M12: 4 | N12: No | O12: Closed | P12: Fixed | Q12: West | R12: =IF(Table1[[#This Row],[Resolution_Time_Hrs]]>Table1[[#This Row],[SLA_Target_Hrs]],"No", "Yes") -> Yes | S12: =IF(Table1[[#This Row],[Calculated_SLA]]=Table1[[#This Row],[SLA_Met]],"Match","Mismatch") -> Match | T12: =IF(Table1[[#This Row],[Calculated_SLA]]="Yes",1,0) -> 1 | U12: =IF(COUNTIFS(Reference_data!A:A,Table1[[#This Row],[Category]],Reference_data!B:B,Table1[[#This Row],[Sub_Category]])>0,"Valid","Invalid") -> Valid | V12: =_xlfn.XLOOKUP([1]!Table1[[#This Row],[Sub_Category]],[1]Reference_data!B:B,[1]Reference_data!A:A) -> Hardware & Mechanical | W12: =IF([1]!Table1[[#This Row],[Category]]=[1]!Table1[[#This Row],[Expected_Category ]],"Valid", "invalid") -> Valid
A13: TKT000012 | B13: Amazon Ltd | C13: 03/05/2026 16:21 | D13: 03/06/2026 05:09 | E13: Connectivity & Software | F13: Network Dropouts | G13: Medium | H13: James | I13: Network Team | J13: 12.8 | K13: 8 | L13: No | M13: 2 | N13: No | O13: Closed | P13: Escalated | Q13: West | R13: =IF(Table1[[#This Row],[Resolution_Time_Hrs]]>Table1[[#This Row],[SLA_Target_Hrs]],"No", "Yes") -> No | S13: =IF(Table1[[#This Row],[Calculated_SLA]]=Table1[[#This Row],[SLA_Met]],"Match","Mismatch") -> Match | T13: =IF(Table1[[#This Row],[Calculated_SLA]]="Yes",1,0) -> 0 | U13: =IF(COUNTIFS(Reference_data!A:A,Table1[[#This Row],[Category]],Reference_data!B:B,Table1[[#This Row],[Sub_Category]])>0,"Valid","Invalid") -> Valid | V13: =_xlfn.XLOOKUP([1]!Table1[[#This Row],[Sub_Category]],[1]Reference_data!B:B,[1]Reference_data!A:A) -> Connectivity & Software | W13: =IF([1]!Table1[[#This Row],[Category]]=[1]!Table1[[#This Row],[Expected_Category ]],"Valid", "invalid") -> Valid
... A18: TKT000017 | B18: HDFC Bank Ltd | C18: 02/15/2026 15:34 | D18: 02/15/2026 20:46 | E18: Supplies & Logistics | F18: Toner Replenishment | G18: Medium | H18: Judy | I18: Logistics Team | J18: 5.2 | K18: 8 | L18: Yes | M18: 4 | N18: No | O18: Closed | P18: Fixed | Q18: North | R18: =IF(Table1[[#This Row],[Resolution_Time_Hrs]]>Table1[[#This Row],[SLA_Target_Hrs]],"No", "Yes") -> Yes | S18: =IF(Table1[[#This Row],[Calculated_SLA]]=Table1[[#This Row],[SLA_Met]],"Match","Mismatch") -> Match | T18: =IF(Table1[[#This Row],[Calculated_SLA]]="Yes",1,0) -> 1 | U18: =IF(COUNTIFS(Reference_data!A:A,Table1[[#This Row],[Category]],Reference_data!B:B,Table1[[#This Row],[Sub_Category]])>0,"Valid","Invalid") -> Valid | V18: =_xlfn.XLOOKUP([1]!Table1[[#This Row],[Sub_Category]],[1]Reference_data!B:B,[1]Reference_data!A:A) -> Supplies & Logistics | W18: =IF([1]!Table1[[#This Row],[Category]]=[1]!Table1[[#This Row],[Expected_Category ]],"Valid", "invalid") -> Valid
A19: TKT000018 | B19: HDFC Bank Ltd | C19: 01/06/2026 12:05 | D19: 01/06/2026 21:17 | E19: Hardware & Mechanical | F19: Device Errors | G19: Medium | H19: Sarah | I19: Hardware Team | J19: 9.2 | K19: 8 | L19: No | N19: Yes | O19: Closed | P19: Escalated | Q19: West | R19: =IF(Table1[[#This Row],[Resolution_Time_Hrs]]>Table1[[#This Row],[SLA_Target_Hrs]],"No", "Yes") -> No | S19: =IF(Table1[[#This Row],[Calculated_SLA]]=Table1[[#This Row],[SLA_Met]],"Match","Mismatch") -> Match | T19: =IF(Table1[[#This Row],[Calculated_SLA]]="Yes",1,0) -> 0 | U19: =IF(COUNTIFS(Reference_data!A:A,Table1[[#This Row],[Category]],Reference_data!B:B,Table1[[#This Row],[Sub_Category]])>0,"Valid","Invalid") -> Valid | V19: =_xlfn.XLOOKUP([1]!Table1[[#This Row],[Sub_Category]],[1]Reference_data!B:B,[1]Reference_data!A:A) -> Hardware & Mechanical | W19: =IF([1]!Table1[[#This Row],[Category]]=[1]!Table1[[#This Row],[Expected_Category ]],"Valid", "invalid") -> Valid
A20: TKT000019 | B20: Bajaj Finance Ltd | C20: 03/13/2026 08:19 | D20: 03/13/2026 14:55 | E20: Connectivity & Software | F20: Driver & Setup | G20: Medium | H20: James | I20: Network Team | J20: 6.6 | K20: 8 | L20: Yes | M20: 4 | N20: No | O20: Closed | P20: Fixed | Q20: East | R20: =IF(Table1[[#This Row],[Resolution_Time_Hrs]]>Table1[[#This Row],[SLA_Target_Hrs]],"No", "Yes") -> Yes | S20: =IF(Table1[[#This Row],[Calculated_SLA]]=Table1[[#This Row],[SLA_Met]],"Match","Mismatch") -> Match | T20: =IF(Table1[[#This Row],[Calculated_SLA]]="Yes",1,0) -> 1 | U20: =IF(COUNTIFS(Reference_data!A:A,Table1[[#This Row],[Category]],Reference_data!B:B,Table1[[#This Row],[Sub_Category]])>0,"Valid","Invalid") -> Valid | V20: =_xlfn.XLOOKUP([1]!Table1[[#This Row],[Sub_Category]],[1]Reference_data!B:B,[1]Reference_data!A:A) -> Connectivity & Software | W20: =IF([1]!Table1[[#This Row],[Category]]=[1]!Table1[[#This Row],[Expected_Category ]],"Valid", "invalid") -> Valid
A21: TKT000020 | B21: HDFC Bank Ltd | C21: 01/07/2026 12:12 | D21: 01/07/2026 17:18 | E21: Print Quality | F21: Defective Prints | G21: Medium | H21: James | I21: Remote Support | J21: 5.1 | K21: 8 | L21: Yes | M21: 4 | N21: No | O21: Closed | P21: Fixed | Q21: West | R21: =IF(Table1[[#This Row],[Resolution_Time_Hrs]]>Table1[[#This Row],[SLA_Target_Hrs]],"No", "Yes") -> Yes | S21: =IF(Table1[[#This Row],[Calculated_SLA]]=Table1[[#This Row],[SLA_Met]],"Match","Mismatch") -> Match | T21: =IF(Table1[[#This Row],[Calculated_SLA]]="Yes",1,0) -> 1 | U21: =IF(COUNTIFS(Reference_data!A:A,Table1[[#This Row],[Category]],Reference_data!B:B,Table1[[#This Row],[Sub_Category]])>0,"Valid","Invalid") -> Valid | V21: =_xlfn.XLOOKUP([1]!Table1[[#This Row],[Sub_Category]],[1]Reference_data!B:B,[1]Reference_data!A:A) -> Print Quality | W21: =IF([1]!Table1[[#This Row],[Category]]=[1]!Table1[[#This Row],[Expected_Category ]],"Valid", "invalid") -> Valid
A22: TKT000021 | B22: Amazon Ltd | C22: 01/17/2026 13:16 | D22: 01/17/2026 22:52 | E22: Connectivity & Software | F22: Network Dropouts | G22: Low | H22: Emma | I22: Network Team | J22: 9.6 | K22: 24 | L22: Yes | M22: 4 | N22: No | O22: Closed | P22: Fixed | Q22: West | R22: =IF(Table1[[#This Row],[Resolution_Time_Hrs]]>Table1[[#This Row],[SLA_Target_Hrs]],"No", "Yes") -> Yes | S22: =IF(Table1[[#This Row],[Calculated_SLA]]=Table1[[#This Row],[SLA_Met]],"Match","Mismatch") -> Match | T22: =IF(Table1[[#This Row],[Calculated_SLA]]="Yes",1,0) -> 1 | U22: =IF(COUNTIFS(Reference_data!A:A,Table1[[#This Row],[Category]],Reference_data!B:B,Table1[[#This Row],[Sub_Category]])>0,"Valid","Invalid") -> Valid | V22: =_xlfn.XLOOKUP([1]!Table1[[#This Row],[Sub_Category]],[1]Reference_data!B:B,[1]Reference_data!A:A) -> Connectivity & Software | W22: =IF([1]!Table1[[#This Row],[Category]]=[1]!Table1[[#This Row],[Expected_Category ]],"Valid", "invalid") -> Valid
A23: TKT000022 | B23: Bajaj Finance Ltd | C23: 02/21/2026 11:24 | D23: 02/21/2026 18:48 | E23: Supplies & Logistics | F23: Paper Supply | G23: Low | H23: Judy | I23: Logistics Team | J23: 7.4 | K23: 24 | L23: Yes | M23: 5 | N23: No | O23: Closed | P23: Fixed | Q23: North | R23: =IF(Table1[[#This Row],[Resolution_Time_Hrs]]>Table1[[#This Row],[SLA_Target_Hrs]],"No", "Yes") -> Yes | S23: =IF(Table1[[#This Row],[Calculated_SLA]]=Table1[[#This Row],[SLA_Met]],"Match","Mismatch") -> Match | T23: =IF(Table1[[#This Row],[Calculated_SLA]]="Yes",1,0) -> 1 | U23: =IF(COUNTIFS(Reference_data!A:A,Table1[[#This Row],[Category]],Reference_data!B:B,Table1[[#This Row],[Sub_Category]])>0,"Valid","Invalid") -> Valid | V23: =_xlfn.XLOOKUP([1]!Table1[[#This Row],[Sub_Category]],[1]Reference_data!B:B,[1]Reference_data!A:A) -> Supplies & Logistics | W23: =IF([1]!Table1[[#This Row],[Category]]=[1]!Table1[[#This Row],[Expected_Category ]],"Valid", "invalid") -> Valid
A24: TKT000023 | B24: Bharti Airtel Ltd | C24: 02/12/2026 11:08 | D24: 02/12/2026 20:14 | E24: Print Quality | F24: Color Calibration | G24: Medium | H24: Jack | I24: Remote Support | J24: 9.1 | K24: 8 | L24: No | N24: Yes | O24: Closed | P24: Temporary Workaround | Q24: East | R24: =IF(Table1[[#This Row],[Resolution_Time_Hrs]]>Table1[[#This Row],[SLA_Target_Hrs]],"No", "Yes") -> No | S24: =IF(Table1[[#This Row],[Calculated_SLA]]=Table1[[#This Row],[SLA_Met]],"Match","Mismatch") -> Match | T24: =IF(Table1[[#This Row],[Calculated_SLA]]="Yes",1,0) -> 0 | U24: =IF(COUNTIFS(Reference_data!A:A,Table1[[#This Row],[Category]],Reference_data!B:B,Table1[[#This Row],[Sub_Category]])>0,"Valid","Invalid") -> Valid | V24: =_xlfn.XLOOKUP([1]!Table1[[#This Row],[Sub_Category]],[1]Reference_data!B:B,[1]Reference_data!A:A) -> Print Quality | W24: =IF([1]!Table1[[#This Row],[Category]]=[1]!Table1[[#This Row],[Expected_Category ]],"Valid", "invalid") -> Valid
A25: TKT000024 | B25: Bajaj Finance Ltd | C25: 02/21/2026 17:41 | D25: 02/22/2026 01:41 | E25: Print Quality | F25: Color Calibration | G25: Medium | H25: Tony | I25: Remote Support | J25: 8 | K25: 8 | L25: Yes | M25: 5 | N25: No | O25: Closed | P25: Fixed | Q25: South | R25: =IF(Table1[[#This Row],[Resolution_Time_Hrs]]>Table1[[#This Row],[SLA_Target_Hrs]],"No", "Yes") -> Yes | S25: =IF(Table1[[#This Row],[Calculated_SLA]]=Table1[[#This Row],[SLA_Met]],"Match","Mismatch") -> Match | T25: =IF(Table1[[#This Row],[Calculated_SLA]]="Yes",1,0) -> 1 | U25: =IF(COUNTIFS(Reference_data!A:A,Table1[[#This Row],[Category]],Reference_data!B:B,Table1[[#This Row],[Sub_Category]])>0,"Valid","Invalid") -> Valid | V25: =_xlfn.XLOOKUP([1]!Table1[[#This Row],[Sub_Category]],[1]Reference_data!B:B,[1]Reference_data!A:A) -> Print Quality | W25: =IF([1]!Table1[[#This Row],[Category]]=[1]!Table1[[#This Row],[Expected_Category ]],"Valid", "invalid") -> Valid
